<sdf version='1.7'>
  <world name='default'>
    <light name='sun' type='directional'>
      <cast_shadows>1</cast_shadows>
      <pose>0 0 10 0 -0 0</pose>
      <diffuse>0.8 0.8 0.8 1</diffuse>
      <specular>0.2 0.2 0.2 1</specular>
      <attenuation>
        <range>1000</range>
        <constant>0.9</constant>
        <linear>0.01</linear>
        <quadratic>0.001</quadratic>
      </attenuation>
      <direction>-0.5 0.1 -0.9</direction>
      <spot>
        <inner_angle>0</inner_angle>
        <outer_angle>0</outer_angle>
        <falloff>0</falloff>
      </spot>
    </light>
    <model name='ground_plane'>
      <static>1</static>
      <link name='link'>
        <collision name='collision'>
          <geometry>
            <plane>
              <normal>0 0 1</normal>
              <size>100 100</size>
            </plane>
          </geometry>
          <surface>
            <contact>
              <collide_bitmask>65535</collide_bitmask>
              <ode/>
            </contact>
            <friction>
              <ode>
                <mu>100</mu>
                <mu2>50</mu2>
              </ode>
              <torsional>
                <ode/>
              </torsional>
            </friction>
            <bounce/>
          </surface>
          <max_contacts>10</max_contacts>
        </collision>
        <visual name='visual'>
          <cast_shadows>0</cast_shadows>
          <geometry>
            <plane>
              <normal>0 0 1</normal>
              <size>100 100</size>
            </plane>
          </geometry>
          <material>
            <script>
              <uri>file://media/materials/scripts/gazebo.material</uri>
              <name>Gazebo/Grey</name>
            </script>
          </material>
        </visual>
        <self_collide>0</self_collide>
        <enable_wind>0</enable_wind>
        <kinematic>0</kinematic>
      </link>
    </model>
    <gravity>0 0 -9.8</gravity>
    <magnetic_field>6e-06 2.3e-05 -4.2e-05</magnetic_field>
    <atmosphere type='adiabatic'/>
    <physics type='ode'>
      <max_step_size>0.001</max_step_size>
      <real_time_factor>1</real_time_factor>
      <real_time_update_rate>1000</real_time_update_rate>
    </physics>
    <scene>
      <ambient>0.4 0.4 0.4 1</ambient>
      <background>0.7 0.7 0.7 1</background>
      <shadows>1</shadows>
    </scene>
    <audio>
      <device>default</device>
    </audio>
    <wind/>
    <spherical_coordinates>
      <surface_model>EARTH_WGS84</surface_model>
      <latitude_deg>0</latitude_deg>
      <longitude_deg>0</longitude_deg>
      <elevation>0</elevation>
      <heading_deg>0</heading_deg>
    </spherical_coordinates>
    <model name='go1'>
      <link name='base'>
        <inertial>
          <pose>0.011605 0.004422 0.000107 0 -0 0</pose>
          <mass>4.801</mass>
          <inertia>
            <ixx>0.0162358</ixx>
            <ixy>0.000591226</ixy>
            <ixz>7.15186e-06</ixz>
            <iyy>0.0366086</iyy>
            <iyz>2.05237e-05</iyz>
            <izz>0.0447997</izz>
          </inertia>
        </inertial>
        <collision name='base_fixed_joint_lump__trunk_collision'>
          <pose>0 0 0 0 -0 0</pose>
          <geometry>
            <box>
              <size>0.3762 0.0935 0.114</size>
            </box>
          </geometry>
          <max_contacts>10</max_contacts>
          <surface>
            <contact>
              <ode/>
            </contact>
            <bounce/>
            <friction>
              <torsional>
                <ode/>
              </torsional>
              <ode/>
            </friction>
          </surface>
        </collision>
        <visual name='base_visual'>
          <pose>0 0 0 0 -0 0</pose>
          <geometry>
            <box>
              <size>0.001 0.001 0.001</size>
            </box>
          </geometry>
        </visual>
        <visual name='base_fixed_joint_lump__trunk_visual_1'>
          <pose>0 0 0 0 -0 0</pose>
          <geometry>
            <mesh>
              <scale>1 1 1</scale>
              <uri>file:///home/kjh/quadruped_sim2sim/install/robot_description/share/robot_description/meshes/trunk.stl</uri>
            </mesh>
          </geometry>
        </visual>
        <visual name='base_fixed_joint_lump__imu_link_visual_2'>
          <pose>-0.01592 -0.06659 -0.00617 0 -0 0</pose>
          <geometry>
            <box>
              <size>0.001 0.001 0.001</size>
            </box>
          </geometry>
        </visual>
        <gravity>1</gravity>
        <sensor name='imu_sensor' type='imu'>
          <always_on>1</always_on>
          <update_rate>1000</update_rate>
          <visualize>1</visualize>
          <topic>__default_topic__</topic>
          <plugin name='imu_plugin' filename='libgazebo_ros_imu_sensor.so'>
            <topicName>trunk_imu</topicName>
            <bodyName>imu_link</bodyName>
            <updateRateHZ>1000.0</updateRateHZ>
            <gaussianNoise>0.0</gaussianNoise>
            <xyzOffset>0 0 0</xyzOffset>
            <rpyOffset>0 0 0</rpyOffset>
            <frameName>imu_link</frameName>
          </plugin>
          <pose>-0.01592 -0.06659 -0.00617 0 -0 0</pose>
          <imu/>
        </sensor>
        <self_collide>0</self_collide>
        <enable_wind>0</enable_wind>
        <kinematic>0</kinematic>
      </link>
      <joint name='FL_hip_joint' type='revolute'>
        <pose relative_to='base'>0.1881 0.04675 0 0 -0 0</pose>
        <parent>base</parent>
        <child>FL_hip</child>
        <axis>
          <xyz>1 0 0</xyz>
          <limit>
            <lower>-0.863</lower>
            <upper>0.863</upper>
            <effort>23.7</effort>
            <velocity>30.1</velocity>
          </limit>
          <dynamics>
            <damping>0</damping>
            <friction>0</friction>
            <spring_reference>0</spring_reference>
            <spring_stiffness>0</spring_stiffness>
          </dynamics>
        </axis>
      </joint>
      <link name='FL_hip'>
        <pose relative_to='FL_hip_joint'>0 0 0 0 -0 0</pose>
        <inertial>
          <pose>-0.00541 -0.00074 6e-06 0 -0 0</pose>
          <mass>0.510299</mass>
          <inertia>
            <ixx>0.000305289</ixx>
            <ixy>-7.78801e-06</ixy>
            <ixz>2.2016e-07</ixz>
            <iyy>0.000590895</iyy>
            <iyz>-1.7175e-08</iyz>
            <izz>0.000396595</izz>
          </inertia>
        </inertial>
        <collision name='FL_hip_collision'>
          <pose>0 0.045 0 1.5708 -0 0</pose>
          <geometry>
            <cylinder>
              <length>0.04</length>
              <radius>0.046</radius>
            </cylinder>
          </geometry>
          <max_contacts>10</max_contacts>
          <surface>
            <contact>
              <ode/>
            </contact>
            <bounce/>
            <friction>
              <torsional>
                <ode/>
              </torsional>
              <ode/>
            </friction>
          </surface>
        </collision>
        <visual name='FL_hip_visual'>
          <pose>0 0 0 0 -0 0</pose>
          <geometry>
            <mesh>
              <scale>1 1 1</scale>
              <uri>file:///home/kjh/quadruped_sim2sim/install/robot_description/share/robot_description/meshes/hip.stl</uri>
            </mesh>
          </geometry>
        </visual>
        <self_collide>0</self_collide>
        <enable_wind>0</enable_wind>
        <kinematic>0</kinematic>
      </link>
      <joint name='FL_thigh_joint' type='revolute'>
        <pose relative_to='FL_hip'>0 0.08 0 0 -0 0</pose>
        <parent>FL_hip</parent>
        <child>FL_thigh</child>
        <axis>
          <xyz>0 1 0</xyz>
          <limit>
            <lower>-0.686</lower>
            <upper>4.501</upper>
            <effort>23.7</effort>
            <velocity>30.1</velocity>
          </limit>
          <dynamics>
            <damping>0</damping>
            <friction>0</friction>
            <spring_reference>0</spring_reference>
            <spring_stiffness>0</spring_stiffness>
          </dynamics>
        </axis>
      </joint>
      <link name='FL_thigh'>
        <pose relative_to='FL_thigh_joint'>0 0 0 0 -0 0</pose>
        <inertial>
          <pose>-0.003468 -0.018947 -0.032736 0 -0 0</pose>
          <mass>0.898919</mass>
          <inertia>
            <ixx>0.00539587</ixx>
            <ixy>1.02809e-07</ixy>
            <ixz>0.000337529</ixz>
            <iyy>0.00514245</iyy>
            <iyz>-5.81656e-06</iyz>
            <izz>0.00102479</izz>
          </inertia>
        </inertial>
        <collision name='FL_thigh_collision'>
          <pose>0 0 -0.1065 3.14159 1.57079 3.14159</pose>
          <geometry>
            <box>
              <size>0.213 0.0245 0.034</size>
            </box>
          </geometry>
          <max_contacts>10</max_contacts>
          <surface>
            <contact>
              <ode/>
            </contact>
            <bounce/>
            <friction>
              <torsional>
                <ode/>
              </torsional>
              <ode/>
            </friction>
          </surface>
        </collision>
        <visual name='FL_thigh_visual'>
          <pose>0 0 0 0 -0 0</pose>
          <geometry>
            <mesh>
              <scale>1 1 1</scale>
              <uri>file:///home/kjh/quadruped_sim2sim/install/robot_description/share/robot_description/meshes/thigh.stl</uri>
            </mesh>
          </geometry>
        </visual>
        <self_collide>0</self_collide>
        <enable_wind>0</enable_wind>
        <kinematic>0</kinematic>
      </link>
      <joint name='FL_calf_joint' type='revolute'>
        <pose relative_to='FL_thigh'>0 0 -0.213 0 -0 0</pose>
        <parent>FL_thigh</parent>
        <child>FL_calf</child>
        <axis>
          <xyz>0 1 0</xyz>
          <limit>
            <lower>-2.818</lower>
            <upper>-0.888</upper>
            <effort>35.55</effort>
            <velocity>20.06</velocity>
          </limit>
          <dynamics>
            <damping>0</damping>
            <friction>0</friction>
            <spring_reference>0</spring_reference>
            <spring_stiffness>0</spring_stiffness>
          </dynamics>
        </axis>
      </joint>
      <link name='FL_calf'>
        <pose relative_to='FL_calf_joint'>0 0 0 0 -0 0</pose>
        <inertial>
          <pose>0.004556 0.000947 -0.147239 0 -0 0</pose>
          <mass>0.218015</mass>
          <inertia>
            <ixx>0.00397532</ixx>
            <ixy>1.13769e-06</ixy>
            <ixz>-0.000157581</ixz>
            <iyy>0.00399608</iyy>
            <iyz>-3.37955e-05</iyz>
            <izz>4.65406e-05</izz>
          </inertia>
        </inertial>
        <collision name='FL_calf_collision'>
          <pose>0 0 -0.1065 3.14159 1.57079 3.14159</pose>
          <geometry>
            <box>
              <size>0.213 0.016 0.016</size>
            </box>
          </geometry>
          <max_contacts>10</max_contacts>
          <surface>
            <contact>
              <ode/>
            </contact>
            <bounce/>
            <friction>
              <torsional>
                <ode/>
              </torsional>
              <ode/>
            </friction>
          </surface>
        </collision>
        <collision name='FL_calf_fixed_joint_lump__FL_foot_collision_1'>
          <pose>0 0 -0.213 0 -0 0</pose>
          <geometry>
            <sphere>
              <radius>0.02</radius>
            </sphere>
          </geometry>
          <max_contacts>10</max_contacts>
          <surface>
            <contact>
              <ode/>
            </contact>
            <bounce/>
            <friction>
              <torsional>
                <ode/>
              </torsional>
              <ode/>
            </friction>
          </surface>
        </collision>
        <visual name='FL_calf_visual'>
          <pose>0 0 0 0 -0 0</pose>
          <geometry>
            <mesh>
              <scale>1 1 1</scale>
              <uri>file:///home/kjh/quadruped_sim2sim/install/robot_description/share/robot_description/meshes/calf.stl</uri>
            </mesh>
          </geometry>
        </visual>
        <visual name='FL_calf_fixed_joint_lump__FL_foot_visual_1'>
          <pose>0 0 -0.213 0 -0 0</pose>
          <geometry>
            <sphere>
              <radius>0.01</radius>
            </sphere>
          </geometry>
        </visual>
        <self_collide>0</self_collide>
        <enable_wind>0</enable_wind>
        <kinematic>0</kinematic>
      </link>
      <joint name='FR_hip_joint' type='revolute'>
        <pose relative_to='base'>0.1881 -0.04675 0 0 -0 0</pose>
        <parent>base</parent>
        <child>FR_hip</child>
        <axis>
          <xyz>1 0 0</xyz>
          <limit>
            <lower>-0.863</lower>
            <upper>0.863</upper>
            <effort>23.7</effort>
            <velocity>30.1</velocity>
          </limit>
          <dynamics>
            <damping>0</damping>
            <friction>0</friction>
            <spring_reference>0</spring_reference>
            <spring_stiffness>0</spring_stiffness>
          </dynamics>
        </axis>
      </joint>
      <link name='FR_hip'>
        <pose relative_to='FR_hip_joint'>0 0 0 0 -0 0</pose>
        <inertial>
          <pose>-0.00541 0.00074 6e-06 0 -0 0</pose>
          <mass>0.510299</mass>
          <inertia>
            <ixx>0.000305289</ixx>
            <ixy>7.78801e-06</ixy>
            <ixz>2.2016e-07</ixz>
            <iyy>0.000590895</iyy>
            <iyz>1.7175e-08</iyz>
            <izz>0.000396595</izz>
          </inertia>
        </inertial>
        <collision name='FR_hip_collision'>
          <pose>0 -0.045 0 1.5708 -0 0</pose>
          <geometry>
            <cylinder>
              <length>0.04</length>
              <radius>0.046</radius>
            </cylinder>
          </geometry>
          <max_contacts>10</max_contacts>
          <surface>
            <contact>
              <ode/>
            </contact>
            <bounce/>
            <friction>
              <torsional>
                <ode/>
              </torsional>
              <ode/>
            </friction>
          </surface>
        </collision>
        <visual name='FR_hip_visual'>
          <pose>0 0 0 -3.14159 0 0</pose>
          <geometry>
            <mesh>
              <scale>1 1 1</scale>
              <uri>file:///home/kjh/quadruped_sim2sim/install/robot_description/share/robot_description/meshes/hip.stl</uri>
            </mesh>
          </geometry>
        </visual>
        <self_collide>0</self_collide>
        <enable_wind>0</enable_wind>
        <kinematic>0</kinematic>
      </link>
      <joint name='FR_thigh_joint' type='revolute'>
        <pose relative_to='FR_hip'>0 -0.08 0 0 -0 0</pose>
        <parent>FR_hip</parent>
        <child>FR_thigh</child>
        <axis>
          <xyz>0 1 0</xyz>
          <limit>
            <lower>-0.686</lower>
            <upper>4.501</upper>
            <effort>23.7</effort>
            <velocity>30.1</velocity>
          </limit>
          <dynamics>
            <damping>0</damping>
            <friction>0</friction>
            <spring_reference>0</spring_reference>
            <spring_stiffness>0</spring_stiffness>
          </dynamics>
        </axis>
      </joint>
      <link name='FR_thigh'>
        <pose relative_to='FR_thigh_joint'>0 0 0 0 -0 0</pose>
        <inertial>
          <pose>-0.003468 0.018947 -0.032736 0 -0 0</pose>
          <mass>0.898919</mass>
          <inertia>
            <ixx>0.00539587</ixx>
            <ixy>-1.02809e-07</ixy>
            <ixz>0.000337529</ixz>
            <iyy>0.00514245</iyy>
            <iyz>5.81656e-06</iyz>
            <izz>0.00102479</izz>
          </inertia>
        </inertial>
        <collision name='FR_thigh_collision'>
          <pose>0 0 -0.1065 3.14159 1.57079 3.14159</pose>
          <geometry>
            <box>
              <size>0.213 0.0245 0.034</size>
            </box>
          </geometry>
          <max_contacts>10</max_contacts>
          <surface>
            <contact>
              <ode/>
            </contact>
            <bounce/>
            <friction>
              <torsional>
                <ode/>
              </torsional>
              <ode/>
            </friction>
          </surface>
        </collision>
        <visual name='FR_thigh_visual'>
          <pose>0 0 0 0 -0 0</pose>
          <geometry>
            <mesh>
              <scale>1 1 1</scale>
              <uri>file:///home/kjh/quadruped_sim2sim/install/robot_description/share/robot_description/meshes/thigh_mirror.stl</uri>
            </mesh>
          </geometry>
        </visual>
        <self_collide>0</self_collide>
        <enable_wind>0</enable_wind>
        <kinematic>0</kinematic>
      </link>
      <joint name='FR_calf_joint' type='revolute'>
        <pose relative_to='FR_thigh'>0 0 -0.213 0 -0 0</pose>
        <parent>FR_thigh</parent>
        <child>FR_calf</child>
        <axis>
          <xyz>0 1 0</xyz>
          <limit>
            <lower>-2.818</lower>
            <upper>-0.888</upper>
            <effort>35.55</effort>
            <velocity>20.06</velocity>
          </limit>
          <dynamics>
            <damping>0</damping>
            <friction>0</friction>
            <spring_reference>0</spring_reference>
            <spring_stiffness>0</spring_stiffness>
          </dynamics>
        </axis>
      </joint>
      <link name='FR_calf'>
        <pose relative_to='FR_calf_joint'>0 0 0 0 -0 0</pose>
        <inertial>
          <pose>0.004556 0.000947 -0.147239 0 -0 0</pose>
          <mass>0.218015</mass>
          <inertia>
            <ixx>0.00397532</ixx>
            <ixy>1.13769e-06</ixy>
            <ixz>-0.000157581</ixz>
            <iyy>0.00399608</iyy>
            <iyz>-3.37955e-05</iyz>
            <izz>4.65406e-05</izz>
          </inertia>
        </inertial>
        <collision name='FR_calf_collision'>
          <pose>0 0 -0.1065 3.14159 1.57079 3.14159</pose>
          <geometry>
            <box>
              <size>0.213 0.016 0.016</size>
            </box>
          </geometry>
          <max_contacts>10</max_contacts>
          <surface>
            <contact>
              <ode/>
            </contact>
            <bounce/>
            <friction>
              <torsional>
                <ode/>
              </torsional>
              <ode/>
            </friction>
          </surface>
        </collision>
        <collision name='FR_calf_fixed_joint_lump__FR_foot_collision_1'>
          <pose>0 0 -0.213 0 -0 0</pose>
          <geometry>
            <sphere>
              <radius>0.02</radius>
            </sphere>
          </geometry>
          <max_contacts>10</max_contacts>
          <surface>
            <contact>
              <ode/>
            </contact>
            <bounce/>
            <friction>
              <torsional>
                <ode/>
              </torsional>
              <ode/>
            </friction>
          </surface>
        </collision>
        <visual name='FR_calf_visual'>
          <pose>0 0 0 0 -0 0</pose>
          <geometry>
            <mesh>
              <scale>1 1 1</scale>
              <uri>file:///home/kjh/quadruped_sim2sim/install/robot_description/share/robot_description/meshes/calf.stl</uri>
            </mesh>
          </geometry>
        </visual>
        <visual name='FR_calf_fixed_joint_lump__FR_foot_visual_1'>
          <pose>0 0 -0.213 0 -0 0</pose>
          <geometry>
            <sphere>
              <radius>0.01</radius>
            </sphere>
          </geometry>
        </visual>
        <self_collide>0</self_collide>
        <enable_wind>0</enable_wind>
        <kinematic>0</kinematic>
      </link>
      <joint name='RL_hip_joint' type='revolute'>
        <pose relative_to='base'>-0.1881 0.04675 0 0 -0 0</pose>
        <parent>base</parent>
        <child>RL_hip</child>
        <axis>
          <xyz>1 0 0</xyz>
          <limit>
            <lower>-0.863</lower>
            <upper>0.863</upper>
            <effort>23.7</effort>
            <velocity>30.1</velocity>
          </limit>
          <dynamics>
            <damping>0</damping>
            <friction>0</friction>
            <spring_reference>0</spring_reference>
            <spring_stiffness>0</spring_stiffness>
          </dynamics>
        </axis>
      </joint>
      <link name='RL_hip'>
        <pose relative_to='RL_hip_joint'>0 0 0 0 -0 0</pose>
        <inertial>
          <pose>0.00541 -0.00074 6e-06 0 -0 0</pose>
          <mass>0.510299</mass>
          <inertia>
            <ixx>0.000305289</ixx>
            <ixy>7.78801e-06</ixy>
            <ixz>-2.2016e-07</ixz>
            <iyy>0.000590895</iyy>
            <iyz>-1.7175e-08</iyz>
            <izz>0.000396595</izz>
          </inertia>
        </inertial>
        <collision name='RL_hip_collision'>
          <pose>0 0.045 0 1.5708 -0 0</pose>
          <geometry>
            <cylinder>
              <length>0.04</length>
              <radius>0.046</radius>
            </cylinder>
          </geometry>
          <max_contacts>10</max_contacts>
          <surface>
            <contact>
              <ode/>
            </contact>
            <bounce/>
            <friction>
              <torsional>
                <ode/>
              </torsional>
              <ode/>
            </friction>
          </surface>
        </collision>
        <visual name='RL_hip_visual'>
          <pose>0 0 0 3.14159 -0 3.14159</pose>
          <geometry>
            <mesh>
              <scale>1 1 1</scale>
              <uri>file:///home/kjh/quadruped_sim2sim/install/robot_description/share/robot_description/meshes/hip.stl</uri>
            </mesh>
          </geometry>
        </visual>
        <self_collide>0</self_collide>
        <enable_wind>0</enable_wind>
        <kinematic>0</kinematic>
      </link>
      <joint name='RL_thigh_joint' type='revolute'>
        <pose relative_to='RL_hip'>0 0.08 0 0 -0 0</pose>
        <parent>RL_hip</parent>
        <child>RL_thigh</child>
        <axis>
          <xyz>0 1 0</xyz>
          <limit>
            <lower>-0.686</lower>
            <upper>4.501</upper>
            <effort>23.7</effort>
            <velocity>30.1</velocity>
          </limit>
          <dynamics>
            <damping>0</damping>
            <friction>0</friction>
            <spring_reference>0</spring_reference>
            <spring_stiffness>0</spring_stiffness>
          </dynamics>
        </axis>
      </joint>
      <link name='RL_thigh'>
        <pose relative_to='RL_thigh_joint'>0 0 0 0 -0 0</pose>
        <inertial>
          <pose>-0.003468 -0.018947 -0.032736 0 -0 0</pose>
          <mass>0.898919</mass>
          <inertia>
            <ixx>0.00539587</ixx>
            <ixy>1.02809e-07</ixy>
            <ixz>0.000337529</ixz>
            <iyy>0.00514245</iyy>
            <iyz>-5.81656e-06</iyz>
            <izz>0.00102479</izz>
          </inertia>
        </inertial>
        <collision name='RL_thigh_collision'>
          <pose>0 0 -0.1065 3.14159 1.57079 3.14159</pose>
          <geometry>
            <box>
              <size>0.213 0.0245 0.034</size>
            </box>
          </geometry>
          <max_contacts>10</max_contacts>
          <surface>
            <contact>
              <ode/>
            </contact>
            <bounce/>
            <friction>
              <torsional>
                <ode/>
              </torsional>
              <ode/>
            </friction>
          </surface>
        </collision>
        <visual name='RL_thigh_visual'>
          <pose>0 0 0 0 -0 0</pose>
          <geometry>
            <mesh>
              <scale>1 1 1</scale>
              <uri>file:///home/kjh/quadruped_sim2sim/install/robot_description/share/robot_description/meshes/thigh.stl</uri>
            </mesh>
          </geometry>
        </visual>
        <self_collide>0</self_collide>
        <enable_wind>0</enable_wind>
        <kinematic>0</kinematic>
      </link>
      <joint name='RL_calf_joint' type='revolute'>
        <pose relative_to='RL_thigh'>0 0 -0.213 0 -0 0</pose>
        <parent>RL_thigh</parent>
        <child>RL_calf</child>
        <axis>
          <xyz>0 1 0</xyz>
          <limit>
            <lower>-2.818</lower>
            <upper>-0.888</upper>
            <effort>35.55</effort>
            <velocity>20.06</velocity>
          </limit>
          <dynamics>
            <damping>0</damping>
            <friction>0</friction>
            <spring_reference>0</spring_reference>
            <spring_stiffness>0</spring_stiffness>
          </dynamics>
        </axis>
      </joint>
      <link name='RL_calf'>
        <pose relative_to='RL_calf_joint'>0 0 0 0 -0 0</pose>
        <inertial>
          <pose>0.004556 0.000947 -0.147239 0 -0 0</pose>
          <mass>0.218015</mass>
          <inertia>
            <ixx>0.00397532</ixx>
            <ixy>1.13769e-06</ixy>
            <ixz>-0.000157581</ixz>
            <iyy>0.00399608</iyy>
            <iyz>-3.37955e-05</iyz>
            <izz>4.65406e-05</izz>
          </inertia>
        </inertial>
        <collision name='RL_calf_collision'>
          <pose>0 0 -0.1065 3.14159 1.57079 3.14159</pose>
          <geometry>
            <box>
              <size>0.213 0.016 0.016</size>
            </box>
          </geometry>
          <max_contacts>10</max_contacts>
          <surface>
            <contact>
              <ode/>
            </contact>
            <bounce/>
            <friction>
              <torsional>
                <ode/>
              </torsional>
              <ode/>
            </friction>
          </surface>
        </collision>
        <collision name='RL_calf_fixed_joint_lump__RL_foot_collision_1'>
          <pose>0 0 -0.213 0 -0 0</pose>
          <geometry>
            <sphere>
              <radius>0.02</radius>
            </sphere>
          </geometry>
          <max_contacts>10</max_contacts>
          <surface>
            <contact>
              <ode/>
            </contact>
            <bounce/>
            <friction>
              <torsional>
                <ode/>
              </torsional>
              <ode/>
            </friction>
          </surface>
        </collision>
        <visual name='RL_calf_visual'>
          <pose>0 0 0 0 -0 0</pose>
          <geometry>
            <mesh>
              <scale>1 1 1</scale>
              <uri>file:///home/kjh/quadruped_sim2sim/install/robot_description/share/robot_description/meshes/calf.stl</uri>
            </mesh>
          </geometry>
        </visual>
        <visual name='RL_calf_fixed_joint_lump__RL_foot_visual_1'>
          <pose>0 0 -0.213 0 -0 0</pose>
          <geometry>
            <sphere>
              <radius>0.01</radius>
            </sphere>
          </geometry>
        </visual>
        <self_collide>0</self_collide>
        <enable_wind>0</enable_wind>
        <kinematic>0</kinematic>
      </link>
      <joint name='RR_hip_joint' type='revolute'>
        <pose relative_to='base'>-0.1881 -0.04675 0 0 -0 0</pose>
        <parent>base</parent>
        <child>RR_hip</child>
        <axis>
          <xyz>1 0 0</xyz>
          <limit>
            <lower>-0.863</lower>
            <upper>0.863</upper>
            <effort>23.7</effort>
            <velocity>30.1</velocity>
          </limit>
          <dynamics>
            <damping>0</damping>
            <friction>0</friction>
            <spring_reference>0</spring_reference>
            <spring_stiffness>0</spring_stiffness>
          </dynamics>
        </axis>
      </joint>
      <link name='RR_hip'>
        <pose relative_to='RR_hip_joint'>0 0 0 0 -0 0</pose>
        <inertial>
          <pose>0.00541 0.00074 6e-06 0 -0 0</pose>
          <mass>0.510299</mass>
          <inertia>
            <ixx>0.000305289</ixx>
            <ixy>-7.78801e-06</ixy>
            <ixz>-2.2016e-07</ixz>
            <iyy>0.000590895</iyy>
            <iyz>1.7175e-08</iyz>
            <izz>0.000396595</izz>
          </inertia>
        </inertial>
        <collision name='RR_hip_collision'>
          <pose>0 -0.045 0 1.5708 -0 0</pose>
          <geometry>
            <cylinder>
              <length>0.04</length>
              <radius>0.046</radius>
            </cylinder>
          </geometry>
          <max_contacts>10</max_contacts>
          <surface>
            <contact>
              <ode/>
            </contact>
            <bounce/>
            <friction>
              <torsional>
                <ode/>
              </torsional>
              <ode/>
            </friction>
          </surface>
        </collision>
        <visual name='RR_hip_visual'>
          <pose>0 0 0 0 -0 3.14159</pose>
          <geometry>
            <mesh>
              <scale>1 1 1</scale>
              <uri>file:///home/kjh/quadruped_sim2sim/install/robot_description/share/robot_description/meshes/hip.stl</uri>
            </mesh>
          </geometry>
        </visual>
        <self_collide>0</self_collide>
        <enable_wind>0</enable_wind>
        <kinematic>0</kinematic>
      </link>
      <joint name='RR_thigh_joint' type='revolute'>
        <pose relative_to='RR_hip'>0 -0.08 0 0 -0 0</pose>
        <parent>RR_hip</parent>
        <child>RR_thigh</child>
        <axis>
          <xyz>0 1 0</xyz>
          <limit>
            <lower>-0.686</lower>
            <upper>4.501</upper>
            <effort>23.7</effort>
            <velocity>30.1</velocity>
          </limit>
          <dynamics>
            <damping>0</damping>
            <friction>0</friction>
            <spring_reference>0</spring_reference>
            <spring_stiffness>0</spring_stiffness>
          </dynamics>
        </axis>
      </joint>
      <link name='RR_thigh'>
        <pose relative_to='RR_thigh_joint'>0 0 0 0 -0 0</pose>
        <inertial>
          <pose>-0.003468 0.018947 -0.032736 0 -0 0</pose>
          <mass>0.898919</mass>
          <inertia>
            <ixx>0.00539587</ixx>
            <ixy>-1.02809e-07</ixy>
            <ixz>0.000337529</ixz>
            <iyy>0.00514245</iyy>
            <iyz>5.81656e-06</iyz>
            <izz>0.00102479</izz>
          </inertia>
        </inertial>
        <collision name='RR_thigh_collision'>
          <pose>0 0 -0.1065 3.14159 1.57079 3.14159</pose>
          <geometry>
            <box>
              <size>0.213 0.0245 0.034</size>
            </box>
          </geometry>
          <max_contacts>10</max_contacts>
          <surface>
            <contact>
              <ode/>
            </contact>
            <bounce/>
            <friction>
              <torsional>
                <ode/>
              </torsional>
              <ode/>
            </friction>
          </surface>
        </collision>
        <visual name='RR_thigh_visual'>
          <pose>0 0 0 0 -0 0</pose>
          <geometry>
            <mesh>
              <scale>1 1 1</scale>
              <uri>file:///home/kjh/quadruped_sim2sim/install/robot_description/share/robot_description/meshes/thigh_mirror.stl</uri>
            </mesh>
          </geometry>
        </visual>
        <self_collide>0</self_collide>
        <enable_wind>0</enable_wind>
        <kinematic>0</kinematic>
      </link>
      <joint name='RR_calf_joint' type='revolute'>
        <pose relative_to='RR_thigh'>0 0 -0.213 0 -0 0</pose>
        <parent>RR_thigh</parent>
        <child>RR_calf</child>
        <axis>
          <xyz>0 1 0</xyz>
          <limit>
            <lower>-2.818</lower>
            <upper>-0.888</upper>
            <effort>35.55</effort>
            <velocity>20.06</velocity>
          </limit>
          <dynamics>
            <damping>0</damping>
            <friction>0</friction>
            <spring_reference>0</spring_reference>
            <spring_stiffness>0</spring_stiffness>
          </dynamics>
        </axis>
      </joint>
      <link name='RR_calf'>
        <pose relative_to='RR_calf_joint'>0 0 0 0 -0 0</pose>
        <inertial>
          <pose>0.004556 0.000947 -0.147239 0 -0 0</pose>
          <mass>0.218015</mass>
          <inertia>
            <ixx>0.00397532</ixx>
            <ixy>1.13769e-06</ixy>
            <ixz>-0.000157581</ixz>
            <iyy>0.00399608</iyy>
            <iyz>-3.37955e-05</iyz>
            <izz>4.65406e-05</izz>
          </inertia>
        </inertial>
        <collision name='RR_calf_collision'>
          <pose>0 0 -0.1065 3.14159 1.57079 3.14159</pose>
          <geometry>
            <box>
              <size>0.213 0.016 0.016</size>
            </box>
          </geometry>
          <max_contacts>10</max_contacts>
          <surface>
            <contact>
              <ode/>
            </contact>
            <bounce/>
            <friction>
              <torsional>
                <ode/>
              </torsional>
              <ode/>
            </friction>
          </surface>
        </collision>
        <collision name='RR_calf_fixed_joint_lump__RR_foot_collision_1'>
          <pose>0 0 -0.213 0 -0 0</pose>
          <geometry>
            <sphere>
              <radius>0.02</radius>
            </sphere>
          </geometry>
          <max_contacts>10</max_contacts>
          <surface>
            <contact>
              <ode/>
            </contact>
            <bounce/>
            <friction>
              <torsional>
                <ode/>
              </torsional>
              <ode/>
            </friction>
          </surface>
        </collision>
        <visual name='RR_calf_visual'>
          <pose>0 0 0 0 -0 0</pose>
          <geometry>
            <mesh>
              <scale>1 1 1</scale>
              <uri>file:///home/kjh/quadruped_sim2sim/install/robot_description/share/robot_description/meshes/calf.stl</uri>
            </mesh>
          </geometry>
        </visual>
        <visual name='RR_calf_fixed_joint_lump__RR_foot_visual_1'>
          <pose>0 0 -0.213 0 -0 0</pose>
          <geometry>
            <sphere>
              <radius>0.01</radius>
            </sphere>
          </geometry>
        </visual>
        <self_collide>0</self_collide>
        <enable_wind>0</enable_wind>
        <kinematic>0</kinematic>
      </link>
      <plugin name='p3d_base_controller' filename='libgazebo_ros_p3d.so'>
        <ros>
          <argument>odom:=odom/ground_truth</argument>
        </ros>
        <body_name>base</body_name>
        <frame_name>world</frame_name>
        <update_rate>250.0</update_rate>
        <xyz_offset>0 0 0</xyz_offset>
        <rpy_offset>0 0 0</rpy_offset>
        <gaussian_noise>0.00001</gaussian_noise>
      </plugin>
      <plugin name='gazebo_ros_init' filename='libgazebo_ros_init.so'>
        <ros>
          <namespace>/</namespace>
        </ros>
      </plugin>
      <plugin name='gazebo_ros_factory' filename='libgazebo_ros_factory.so'>
        <ros>
          <namespace>/</namespace>
        </ros>
      </plugin>
      <plugin name='gazebo_ros_state' filename='libgazebo_ros_state.so'>
        <ros>
          <namespace>/</namespace>
        </ros>
      </plugin>
      <static>0</static>
      <plugin name='gazebo_ros2_control' filename='libgazebo_ros2_control.so'>
        <parameters>/home/kjh/quadruped_sim2sim/install/robot_gazebo/share/robot_gazebo/config/go1_ros_control.yaml</parameters>
      </plugin>
      <pose>0 0 0.4 0 -0 0</pose>
    </model>
    <model name='unit_box_clone_0_clone_clone'>
      <pose>1.79924 -0.104625 0.034537 0 -0 0</pose>
      <link name='link'>
        <inertial>
          <mass>1</mass>
          <inertia>
            <ixx>0.166667</ixx>
            <ixy>0</ixy>
            <ixz>0</ixz>
            <iyy>0.166667</iyy>
            <iyz>0</iyz>
            <izz>0.166667</izz>
          </inertia>
          <pose>0 0 0 0 -0 0</pose>
        </inertial>
        <collision name='collision'>
          <geometry>
            <box>
              <size>1 1 0.105879</size>
            </box>
          </geometry>
          <max_contacts>10</max_contacts>
          <surface>
            <contact>
              <ode/>
            </contact>
            <bounce/>
            <friction>
              <torsional>
                <ode/>
              </torsional>
              <ode/>
            </friction>
          </surface>
        </collision>
        <visual name='visual'>
          <geometry>
            <box>
              <size>1 1 0.105879</size>
            </box>
          </geometry>
          <material>
            <script>
              <name>Gazebo/Grey</name>
              <uri>file://media/materials/scripts/gazebo.material</uri>
            </script>
          </material>
        </visual>
        <self_collide>0</self_collide>
        <enable_wind>0</enable_wind>
        <kinematic>1</kinematic>
      </link>
    </model>
    <model name='unit_box_clone_0_clone_clone_clone'>
      <pose>2.19726 -0.128562 0.034537 0 -0 0</pose>
      <link name='link'>
        <inertial>
          <mass>1</mass>
          <inertia>
            <ixx>0.166667</ixx>
            <ixy>0</ixy>
            <ixz>0</ixz>
            <iyy>0.166667</iyy>
            <iyz>0</iyz>
            <izz>0.166667</izz>
          </inertia>
          <pose>0 0 0 0 -0 0</pose>
        </inertial>
        <collision name='collision'>
          <geometry>
            <box>
              <size>1 4.16528 0.105879</size>
            </box>
          </geometry>
          <max_contacts>10</max_contacts>
          <surface>
            <contact>
              <ode/>
            </contact>
            <bounce/>
            <friction>
              <torsional>
                <ode/>
              </torsional>
              <ode/>
            </friction>
          </surface>
        </collision>
        <visual name='visual'>
          <geometry>
            <box>
              <size>1 4.16528 0.105879</size>
            </box>
          </geometry>
          <material>
            <script>
              <name>Gazebo/Grey</name>
              <uri>file://media/materials/scripts/gazebo.material</uri>
            </script>
          </material>
        </visual>
        <self_collide>0</self_collide>
        <enable_wind>0</enable_wind>
        <kinematic>1</kinematic>
      </link>
    </model>
    <model name='unit_box_clone_0_clone_clone_clone_0'>
      <pose>2.45587 -0.129868 0.034537 0 -0 0</pose>
      <link name='link'>
        <inertial>
          <mass>1</mass>
          <inertia>
            <ixx>0.166667</ixx>
            <ixy>0</ixy>
            <ixz>0</ixz>
            <iyy>0.166667</iyy>
            <iyz>0</iyz>
            <izz>0.166667</izz>
          </inertia>
          <pose>0 0 0 0 -0 0</pose>
        </inertial>
        <collision name='collision'>
          <geometry>
            <box>
              <size>1 4.16528 0.105879</size>
            </box>
          </geometry>
          <max_contacts>10</max_contacts>
          <surface>
            <contact>
              <ode/>
            </contact>
            <bounce/>
            <friction>
              <torsional>
                <ode/>
              </torsional>
              <ode/>
            </friction>
          </surface>
        </collision>
        <visual name='visual'>
          <geometry>
            <box>
              <size>1 4.16528 0.105879</size>
            </box>
          </geometry>
          <material>
            <script>
              <name>Gazebo/Grey</name>
              <uri>file://media/materials/scripts/gazebo.material</uri>
            </script>
          </material>
        </visual>
        <self_collide>0</self_collide>
        <enable_wind>0</enable_wind>
        <kinematic>1</kinematic>
      </link>
    </model>
    <model name='unit_box_clone_0_clone_clone_clone_0_clone'>
      <pose>2.72862 -0.130825 0.034537 0 -0 0</pose>
      <link name='link'>
        <inertial>
          <mass>1</mass>
          <inertia>
            <ixx>0.166667</ixx>
            <ixy>0</ixy>
            <ixz>0</ixz>
            <iyy>0.166667</iyy>
            <iyz>0</iyz>
            <izz>0.166667</izz>
          </inertia>
          <pose>0 0 0 0 -0 0</pose>
        </inertial>
        <collision name='collision'>
          <geometry>
            <box>
              <size>1 4.16528 0.569383</size>
            </box>
          </geometry>
          <max_contacts>10</max_contacts>
          <surface>
            <contact>
              <ode/>
            </contact>
            <bounce/>
            <friction>
              <torsional>
                <ode/>
              </torsional>
              <ode/>
            </friction>
          </surface>
        </collision>
        <visual name='visual'>
          <geometry>
            <box>
              <size>1 4.16528 0.569383</size>
            </box>
          </geometry>
          <material>
            <script>
              <name>Gazebo/Grey</name>
              <uri>file://media/materials/scripts/gazebo.material</uri>
            </script>
          </material>
        </visual>
        <self_collide>0</self_collide>
        <enable_wind>0</enable_wind>
        <kinematic>1</kinematic>
      </link>
    </model>
    <model name='unit_box_clone_0_clone_clone_clone_0_clone_0'>
      <pose>3.07183 -0.126437 0.034537 0 -0 0</pose>
      <link name='link'>
        <inertial>
          <mass>1</mass>
          <inertia>
            <ixx>0.166667</ixx>
            <ixy>0</ixy>
            <ixz>0</ixz>
            <iyy>0.166667</iyy>
            <iyz>0</iyz>
            <izz>0.166667</izz>
          </inertia>
          <pose>0 0 0 0 -0 0</pose>
        </inertial>
        <collision name='collision'>
          <geometry>
            <box>
              <size>1 4.16528 0.569383</size>
            </box>
          </geometry>
          <max_contacts>10</max_contacts>
          <surface>
            <contact>
              <ode/>
            </contact>
            <bounce/>
            <friction>
              <torsional>
                <ode/>
              </torsional>
              <ode/>
            </friction>
          </surface>
        </collision>
        <visual name='visual'>
          <geometry>
            <box>
              <size>1 4.16528 0.569383</size>
            </box>
          </geometry>
          <material>
            <script>
              <name>Gazebo/Grey</name>
              <uri>file://media/materials/scripts/gazebo.material</uri>
            </script>
          </material>
        </visual>
        <self_collide>0</self_collide>
        <enable_wind>0</enable_wind>
        <kinematic>1</kinematic>
      </link>
    </model>
    <model name='unit_box_clone_0_clone_clone_clone_0_clone_0_clone'>
      <pose>3.94383 -0.126661 0.034537 0 -0 0</pose>
      <link name='link'>
        <inertial>
          <mass>1</mass>
          <inertia>
            <ixx>0.166667</ixx>
            <ixy>0</ixy>
            <ixz>0</ixz>
            <iyy>0.166667</iyy>
            <iyz>0</iyz>
            <izz>0.166667</izz>
          </inertia>
          <pose>0 0 0 0 -0 0</pose>
        </inertial>
        <collision name='collision'>
          <geometry>
            <box>
              <size>1 4.16528 0.569383</size>
            </box>
          </geometry>
          <max_contacts>10</max_contacts>
          <surface>
            <contact>
              <ode/>
            </contact>
            <bounce/>
            <friction>
              <torsional>
                <ode/>
              </torsional>
              <ode/>
            </friction>
          </surface>
        </collision>
        <visual name='visual'>
          <geometry>
            <box>
              <size>1 4.16528 0.569383</size>
            </box>
          </geometry>
          <material>
            <script>
              <name>Gazebo/Grey</name>
              <uri>file://media/materials/scripts/gazebo.material</uri>
            </script>
          </material>
        </visual>
        <self_collide>0</self_collide>
        <enable_wind>0</enable_wind>
        <kinematic>1</kinematic>
      </link>
    </model>
    <model name='unit_box_clone_0_clone_clone_clone_0_clone_0_clone_clone'>
      <pose>4.43607 -0.124263 0.034537 0 -0 0</pose>
      <link name='link'>
        <inertial>
          <mass>1</mass>
          <inertia>
            <ixx>0.166667</ixx>
            <ixy>0</ixy>
            <ixz>0</ixz>
            <iyy>0.166667</iyy>
            <iyz>0</iyz>
            <izz>0.166667</izz>
          </inertia>
          <pose>0 0 0 0 -0 0</pose>
        </inertial>
        <collision name='collision'>
          <geometry>
            <box>
              <size>1 4.16528 0.815059</size>
            </box>
          </geometry>
          <max_contacts>10</max_contacts>
          <surface>
            <contact>
              <ode/>
            </contact>
            <bounce/>
            <friction>
              <torsional>
                <ode/>
              </torsional>
              <ode/>
            </friction>
          </surface>
        </collision>
        <visual name='visual'>
          <geometry>
            <box>
              <size>1 4.16528 0.815059</size>
            </box>
          </geometry>
          <material>
            <script>
              <name>Gazebo/Grey</name>
              <uri>file://media/materials/scripts/gazebo.material</uri>
            </script>
          </material>
        </visual>
        <self_collide>0</self_collide>
        <enable_wind>0</enable_wind>
        <kinematic>1</kinematic>
      </link>
    </model>
    <model name='unit_box_clone_0_clone_clone_clone_0_clone_0_clone_clone_clone'>
      <pose>5.13455 -0.107111 0.034537 0 -0 0</pose>
      <link name='link'>
        <inertial>
          <mass>1</mass>
          <inertia>
            <ixx>0.166667</ixx>
            <ixy>0</ixy>
            <ixz>0</ixz>
            <iyy>0.166667</iyy>
            <iyz>0</iyz>
            <izz>0.166667</izz>
          </inertia>
          <pose>0 0 0 0 -0 0</pose>
        </inertial>
        <collision name='collision'>
          <geometry>
            <box>
              <size>1 4.16528 0.49773</size>
            </box>
          </geometry>
          <max_contacts>10</max_contacts>
          <surface>
            <contact>
              <ode/>
            </contact>
            <bounce/>
            <friction>
              <torsional>
                <ode/>
              </torsional>
              <ode/>
            </friction>
          </surface>
        </collision>
        <visual name='visual'>
          <geometry>
            <box>
              <size>1 4.16528 0.49773</size>
            </box>
          </geometry>
          <material>
            <script>
              <name>Gazebo/Grey</name>
              <uri>file://media/materials/scripts/gazebo.material</uri>
            </script>
          </material>
        </visual>
        <self_collide>0</self_collide>
        <enable_wind>0</enable_wind>
        <kinematic>1</kinematic>
      </link>
    </model>
    <model name='unit_box_clone_0_clone_clone_clone_0_clone_0_clone_clone_clone_clone'>
      <pose>6.54045 -0.168541 0.034537 0 -0 0</pose>
      <link name='link'>
        <inertial>
          <mass>1</mass>
          <inertia>
            <ixx>0.166667</ixx>
            <ixy>0</ixy>
            <ixz>0</ixz>
            <iyy>0.166667</iyy>
            <iyz>0</iyz>
            <izz>0.166667</izz>
          </inertia>
          <pose>0 0 0 0 -0 0</pose>
        </inertial>
        <collision name='collision'>
          <geometry>
            <box>
              <size>1 4.16528 0.236937</size>
            </box>
          </geometry>
          <max_contacts>10</max_contacts>
          <surface>
            <contact>
              <ode/>
            </contact>
            <bounce/>
            <friction>
              <torsional>
                <ode/>
              </torsional>
              <ode/>
            </friction>
          </surface>
        </collision>
        <visual name='visual'>
          <geometry>
            <box>
              <size>1 4.16528 0.236937</size>
            </box>
          </geometry>
          <material>
            <script>
              <name>Gazebo/Grey</name>
              <uri>file://media/materials/scripts/gazebo.material</uri>
            </script>
          </material>
        </visual>
        <self_collide>0</self_collide>
        <enable_wind>0</enable_wind>
        <kinematic>1</kinematic>
      </link>
    </model>
    <model name='unit_box_clone_0_clone_clone_clone_0_clone_0_clone_clone_clone_clone_clone'>
      <pose>7.23173 -0.15091 0.034537 0 -0 0</pose>
      <link name='link'>
        <inertial>
          <mass>1</mass>
          <inertia>
            <ixx>0.166667</ixx>
            <ixy>0</ixy>
            <ixz>0</ixz>
            <iyy>0.166667</iyy>
            <iyz>0</iyz>
            <izz>0.166667</izz>
          </inertia>
          <pose>0 0 0 0 -0 0</pose>
        </inertial>
        <collision name='collision'>
          <geometry>
            <box>
              <size>0.18698 4.16528 0.236937</size>
            </box>
          </geometry>
          <max_contacts>10</max_contacts>
          <surface>
            <contact>
              <ode/>
            </contact>
            <bounce/>
            <friction>
              <torsional>
                <ode/>
              </torsional>
              <ode/>
            </friction>
          </surface>
        </collision>
        <visual name='visual'>
          <geometry>
            <box>
              <size>0.18698 4.16528 0.236937</size>
            </box>
          </geometry>
          <material>
            <script>
              <name>Gazebo/Grey</name>
              <uri>file://media/materials/scripts/gazebo.material</uri>
            </script>
          </material>
        </visual>
        <self_collide>0</self_collide>
        <enable_wind>0</enable_wind>
        <kinematic>1</kinematic>
      </link>
    </model>
    <model name='unit_box_clone_0_clone_clone_clone_0_clone_0_clone_clone_clone_clone_clone_0'>
      <pose>7.99334 -0.131616 0.034537 0 -0 0</pose>
      <link name='link'>
        <inertial>
          <mass>1</mass>
          <inertia>
            <ixx>0.166667</ixx>
            <ixy>0</ixy>
            <ixz>0</ixz>
            <iyy>0.166667</iyy>
            <iyz>0</iyz>
            <izz>0.166667</izz>
          </inertia>
          <pose>0 0 0 0 -0 0</pose>
        </inertial>
        <collision name='collision'>
          <geometry>
            <box>
              <size>0.18698 4.16528 0.236936</size>
            </box>
          </geometry>
          <max_contacts>10</max_contacts>
          <surface>
            <contact>
              <ode/>
            </contact>
            <bounce/>
            <friction>
              <torsional>
                <ode/>
              </torsional>
              <ode/>
            </friction>
          </surface>
        </collision>
        <visual name='visual'>
          <geometry>
            <box>
              <size>0.18698 4.16528 0.236936</size>
            </box>
          </geometry>
          <material>
            <script>
              <name>Gazebo/Grey</name>
              <uri>file://media/materials/scripts/gazebo.material</uri>
            </script>
          </material>
        </visual>
        <self_collide>0</self_collide>
        <enable_wind>0</enable_wind>
        <kinematic>1</kinematic>
      </link>
    </model>
    <model name='unit_box_clone_0_clone_clone_clone_0_clone_0_clone_clone_clone_clone_clone_1'>
      <pose>8.43642 -0.013101 0.034537 0 -0 0</pose>
      <link name='link'>
        <inertial>
          <mass>1</mass>
          <inertia>
            <ixx>0.166667</ixx>
            <ixy>0</ixy>
            <ixz>0</ixz>
            <iyy>0.166667</iyy>
            <iyz>0</iyz>
            <izz>0.166667</izz>
          </inertia>
          <pose>0 0 0 0 -0 0</pose>
        </inertial>
        <collision name='collision'>
          <geometry>
            <box>
              <size>0.18698 4.16528 0.236935</size>
            </box>
          </geometry>
          <max_contacts>10</max_contacts>
          <surface>
            <contact>
              <ode/>
            </contact>
            <bounce/>
            <friction>
              <torsional>
                <ode/>
              </torsional>
              <ode/>
            </friction>
          </surface>
        </collision>
        <visual name='visual'>
          <geometry>
            <box>
              <size>0.18698 4.16528 0.236935</size>
            </box>
          </geometry>
          <material>
            <script>
              <name>Gazebo/Grey</name>
              <uri>file://media/materials/scripts/gazebo.material</uri>
            </script>
          </material>
        </visual>
        <self_collide>0</self_collide>
        <enable_wind>0</enable_wind>
        <kinematic>1</kinematic>
      </link>
    </model>
    <state world_name='default'>
      <sim_time>910 773000000</sim_time>
      <real_time>911 991890209</real_time>
      <wall_time>1745151516 148356607</wall_time>
      <iterations>910773</iterations>
      <model name='go1'>
        <pose>-0.008223 -0.000958 0.318981 0.007535 -0.003651 0.006247</pose>
        <scale>1 1 1</scale>
        <link name='FL_calf'>
          <pose>0.024929 0.136182 0.178978 0.094404 -0.723167 -0.055985</pose>
          <velocity>1e-06 4e-06 -1e-06 2.4e-05 -3e-06 5e-06</velocity>
          <acceleration>2e-06 2e-06 1e-06 0.552901 -0.953337 -2.44082</acceleration>
          <wrench>1e-06 1e-06 0 0 -0 0</wrench>
        </link>
        <link name='FL_hip'>
          <pose>0.179579 0.046965 0.320021 0.070895 -0.003651 0.006213</pose>
          <velocity>-1e-06 1e-06 -1e-06 2.4e-05 -0 6e-06</velocity>
          <acceleration>1e-06 -0 8e-06 -1.39618 -0.718447 1.49259</acceleration>
          <wrench>1e-06 -0 4e-06 0 -0 0</wrench>
        </link>
        <link name='FL_thigh'>
          <pose>0.179058 0.126762 0.325689 0.102485 0.805957 0.08054</pose>
          <velocity>-1e-06 1e-06 1e-06 2.4e-05 -1.4e-05 5e-06</velocity>
          <acceleration>1e-06 0 9e-06 0.691422 -1.02075 0.237827</acceleration>
          <wrench>1e-06 0 8e-06 0 -0 0</wrench>
        </link>
        <link name='FR_calf'>
          <pose>0.014958 -0.133961 0.189579 -0.061003 -0.647444 0.042839</pose>
          <velocity>1e-06 -2e-06 0 -2.1e-05 3e-06 5e-06</velocity>
          <acceleration>2e-06 -1e-06 1e-06 1.68321 -0.193639 2.94421</acceleration>
          <wrench>1e-06 -0 0 0 -0 0</wrench>
        </link>
        <link name='FR_hip'>
          <pose>0.180165 -0.046531 0.319316 -0.048737 -0.003651 0.006272</pose>
          <velocity>-0 1e-06 -1e-06 -2.1e-05 -1e-06 6e-06</velocity>
          <acceleration>2e-06 -1e-06 1e-05 0.132681 -0.365262 0.317228</acceleration>
          <wrench>1e-06 -0 5e-06 0 -0 0</wrench>
        </link>
        <link name='FR_thigh'>
          <pose>0.18065 -0.126435 0.323215 -0.077497 0.89016 -0.054184</pose>
          <velocity>0 1e-06 1e-06 -2.1e-05 -5e-06 6e-06</velocity>
          <acceleration>2e-06 -1e-06 9e-06 2.09966 -0.305607 1.63557</acceleration>
          <wrench>2e-06 -1e-06 8e-06 0 -0 0</wrench>
        </link>
        <link name='RL_calf'>
          <pose>-0.377046 0.12995 0.209421 0.06528 -0.47082 -0.02317</pose>
          <velocity>-1e-06 -1e-06 -1e-06 9e-06 -6e-06 5e-06</velocity>
          <acceleration>-0 -1e-06 -0 -1.01047 0.709717 -0.330251</acceleration>
          <wrench>-0 -0 -0 0 -0 0</wrench>
        </link>
        <link name='RL_hip'>
          <pose>-0.196611 0.044614 0.318647 0.058187 -0.00365 0.00624</pose>
          <velocity>-1e-06 -1e-06 -1e-06 9e-06 -1e-06 6e-06</velocity>
          <acceleration>1e-06 -2e-06 -2e-06 1.29852 -0.809714 -1.5819</acceleration>
          <wrench>1e-06 -1e-06 -1e-06 0 -0 0</wrench>
        </link>
        <link name='RL_thigh'>
          <pose>-0.197128 0.124477 0.3233 0.108347 1.00297 0.0979</pose>
          <velocity>-1e-06 -1e-06 -0 9e-06 -2e-06 6e-06</velocity>
          <acceleration>1e-06 -2e-06 -1e-06 1.41412 1.37603 -1.91447</acceleration>
          <wrench>1e-06 -2e-06 -1e-06 0 -0 0</wrench>
        </link>
        <link name='RR_calf'>
          <pose>-0.37197 -0.137552 0.204145 -0.075268 -0.52168 0.043534</pose>
          <velocity>0 -2e-06 -0 -7e-06 -1e-06 6e-06</velocity>
          <acceleration>1e-06 -2e-06 0 2.47056 1.49223 0.401882</acceleration>
          <wrench>0 -0 0 0 -0 0</wrench>
        </link>
        <link name='RR_hip'>
          <pose>-0.196025 -0.048881 0.317942 -0.065283 -0.003652 0.006244</pose>
          <velocity>-0 -1e-06 -1e-06 -7e-06 -1e-06 6e-06</velocity>
          <acceleration>2e-06 -2e-06 -0 -0.616928 -0.78859 2.78981</acceleration>
          <wrench>1e-06 -1e-06 -0 0 -0 0</wrench>
        </link>
        <link name='RR_thigh'>
          <pose>-0.195546 -0.128709 0.323162 -0.116238 0.973311 -0.090223</pose>
          <velocity>0 -1e-06 -0 -7e-06 1e-06 6e-06</velocity>
          <acceleration>2e-06 -3e-06 1e-06 2.22205 1.53807 -1.27674</acceleration>
          <wrench>1e-06 -2e-06 1e-06 0 -0 0</wrench>
        </link>
        <link name='base'>
          <pose>-0.008223 -0.000958 0.318981 0.007535 -0.003651 0.006247</pose>
          <velocity>-0 0 -1e-06 0 -1e-06 6e-06</velocity>
          <acceleration>1e-06 -1e-06 4e-06 -0.00281 -0.039895 -0.025343</acceleration>
          <wrench>6e-06 -7e-06 2e-05 0 -0 0</wrench>
        </link>
      </model>
      <model name='ground_plane'>
        <pose>0 0 0 0 -0 0</pose>
        <scale>1 1 1</scale>
        <link name='link'>
          <pose>0 0 0 0 -0 0</pose>
          <velocity>0 0 0 0 -0 0</velocity>
          <acceleration>0 0 0 0 -0 0</acceleration>
          <wrench>0 0 0 0 -0 0</wrench>
        </link>
      </model>
      <model name='unit_box_clone_0_clone_clone'>
        <pose>1.79924 -0.104625 0.034537 0 -0 0</pose>
        <scale>1 4.16528 1</scale>
        <link name='link'>
          <pose>1.79924 -0.104625 0.034537 0 -0 0</pose>
          <velocity>0 0 0 0 -0 0</velocity>
          <acceleration>0 0 -9.8 0 -0 0</acceleration>
          <wrench>0 0 -9.8 0 -0 0</wrench>
        </link>
      </model>
      <model name='unit_box_clone_0_clone_clone_clone'>
        <pose>2.19726 -0.128562 0.034537 0 -0 0</pose>
        <scale>1 1 3.10163</scale>
        <link name='link'>
          <pose>2.19726 -0.128562 0.034537 0 -0 0</pose>
          <velocity>0 0 0 0 -0 0</velocity>
          <acceleration>0 0 -9.8 0 -0 0</acceleration>
          <wrench>0 0 -9.8 0 -0 0</wrench>
        </link>
      </model>
      <model name='unit_box_clone_0_clone_clone_clone_0'>
        <pose>2.45587 -0.129868 0.034537 0 -0 0</pose>
        <scale>1 1 5.37768</scale>
        <link name='link'>
          <pose>2.45587 -0.129868 0.034537 0 -0 0</pose>
          <velocity>0 0 0 0 -0 0</velocity>
          <acceleration>0 0 -9.8 0 -0 0</acceleration>
          <wrench>0 0 -9.8 0 -0 0</wrench>
        </link>
      </model>
      <model name='unit_box_clone_0_clone_clone_clone_0_clone'>
        <pose>2.72862 -0.130825 0.034537 0 -0 0</pose>
        <scale>1 1 1.35637</scale>
        <link name='link'>
          <pose>2.72862 -0.130825 0.034537 0 -0 0</pose>
          <velocity>0 0 0 0 -0 0</velocity>
          <acceleration>0 0 -9.8 0 -0 0</acceleration>
          <wrench>0 0 -9.8 0 -0 0</wrench>
        </link>
      </model>
      <model name='unit_box_clone_0_clone_clone_clone_0_clone_0'>
        <pose>3.07183 -0.126437 0.034537 0 -0 0</pose>
        <scale>1 1 1</scale>
        <link name='link'>
          <pose>3.07183 -0.126437 0.034537 0 -0 0</pose>
          <velocity>0 0 0 0 -0 0</velocity>
          <acceleration>0 0 -9.8 0 -0 0</acceleration>
          <wrench>0 0 -9.8 0 -0 0</wrench>
        </link>
      </model>
      <model name='unit_box_clone_0_clone_clone_clone_0_clone_0_clone'>
        <pose>3.94383 -0.126661 0.034537 0 -0 0</pose>
        <scale>1 1 1.43148</scale>
        <link name='link'>
          <pose>3.94383 -0.126661 0.034537 0 -0 0</pose>
          <velocity>0 0 0 0 -0 0</velocity>
          <acceleration>0 0 -9.8 0 -0 0</acceleration>
          <wrench>0 0 -9.8 0 -0 0</wrench>
        </link>
      </model>
      <model name='unit_box_clone_0_clone_clone_clone_0_clone_0_clone_clone'>
        <pose>4.43607 -0.124263 0.034537 0 -0 0</pose>
        <scale>1 1 0.610667</scale>
        <link name='link'>
          <pose>4.43607 -0.124263 0.034537 0 -0 0</pose>
          <velocity>0 0 0 0 -0 0</velocity>
          <acceleration>0 0 -9.8 0 -0 0</acceleration>
          <wrench>0 0 -9.8 0 -0 0</wrench>
        </link>
      </model>
      <model name='unit_box_clone_0_clone_clone_clone_0_clone_0_clone_clone_clone'>
        <pose>5.13455 -0.107111 0.034537 0 -0 0</pose>
        <scale>1 1 0.476034</scale>
        <link name='link'>
          <pose>5.13455 -0.107111 0.034537 0 -0 0</pose>
          <velocity>0 0 0 0 -0 0</velocity>
          <acceleration>0 0 -9.8 0 -0 0</acceleration>
          <wrench>0 0 -9.8 0 -0 0</wrench>
        </link>
      </model>
      <model name='unit_box_clone_0_clone_clone_clone_0_clone_0_clone_clone_clone_clone'>
        <pose>6.54045 -0.168541 0.034537 0 -0 0</pose>
        <scale>0.18698 1 0.575804</scale>
        <link name='link'>
          <pose>6.54045 -0.168541 0.034537 0 -0 0</pose>
          <velocity>0 0 0 0 -0 0</velocity>
          <acceleration>0 0 -9.8 0 -0 0</acceleration>
          <wrench>0 0 -9.8 0 -0 0</wrench>
        </link>
      </model>
      <model name='unit_box_clone_0_clone_clone_clone_0_clone_0_clone_clone_clone_clone_clone'>
        <pose>7.23173 -0.15091 0.034537 0 -0 0</pose>
        <scale>1 1 0.617971</scale>
        <link name='link'>
          <pose>7.23173 -0.15091 0.034537 0 -0 0</pose>
          <velocity>0 0 0 0 -0 0</velocity>
          <acceleration>0 0 -9.8 0 -0 0</acceleration>
          <wrench>0 0 -9.8 0 -0 0</wrench>
        </link>
      </model>
      <model name='unit_box_clone_0_clone_clone_clone_0_clone_0_clone_clone_clone_clone_clone_0'>
        <pose>7.99334 -0.131616 0.034537 0 -0 0</pose>
        <scale>1 1 0.547844</scale>
        <link name='link'>
          <pose>7.99334 -0.131616 0.034537 0 -0 0</pose>
          <velocity>0 0 0 0 -0 0</velocity>
          <acceleration>0 0 -9.8 0 -0 0</acceleration>
          <wrench>0 0 -9.8 0 -0 0</wrench>
        </link>
      </model>
      <model name='unit_box_clone_0_clone_clone_clone_0_clone_0_clone_clone_clone_clone_clone_1'>
        <pose>8.43642 -0.013101 0.034537 0 -0 0</pose>
        <scale>1 1 0.446578</scale>
        <link name='link'>
          <pose>8.43642 -0.013101 0.034537 0 -0 0</pose>
          <velocity>0 0 0 0 -0 0</velocity>
          <acceleration>0 0 -9.8 0 -0 0</acceleration>
          <wrench>0 0 -9.8 0 -0 0</wrench>
        </link>
      </model>
      <light name='sun'>
        <pose>0 0 10 0 -0 0</pose>
      </light>
    </state>
    <gui fullscreen='0'>
      <camera name='user_camera'>
        <pose>2.7924 -8.24668 1.06097 0 -0.000357 1.44821</pose>
        <view_controller>orbit</view_controller>
        <projection_type>perspective</projection_type>
      </camera>
    </gui>
  </world>
</sdf>
